<?xml version="1.0"?>
<robot name="custom_bot">

    <link name="base_link">
        <visual>
            <geometry>
                <box size="0.6 0.3 0.3" />
            </geometry>
            <material name="red">
                <color rgba=".1 0.6 0.8 .5" />
            </material>
        </visual>


    </link>


    <link name="front_right_wheel">
        <visual>
            <geometry>
                <cylinder radius="0.15" length="0.1" />
            </geometry>
            <material>
                <color rgba="0.4 0.8 0.1 1" />
            </material>
        </visual>

    </link>

    <joint name="front_right_wheel_joint" type="continuous">
        <axis xyz="0.0 0.0 1" />
        <parent link="base_link" />
        <child link="front_right_wheel" />
        <origin xyz=".3 .2 -.05" rpy="-1.5708 0.0 0.0" />

    </joint>
    <link name="front_left_wheel">
        <visual>
            <geometry>
                <cylinder radius="0.15" length="0.1" />
            </geometry>
            <material>
                <color rgba="0.4 0.8 0.1 1" />
            </material>

        </visual>

    </link>

    <joint name="front_left_wheel_joint" type="continuous">
        <axis xyz="0.0 0.0 1" />
        <parent link="base_link" />
        <child link="front_left_wheel" />
        <origin xyz=".3 -.2 -.05" rpy="-1.5708 0.0 0.0" />

    </joint>

    <link name="right_wheel">
        <visual>
            <geometry>
                <cylinder radius="0.25" length="0.1" />
            </geometry>
            <material name="black">
                <color rgba="0.5 0.1 0.5 1" />
            </material>
        </visual>

    </link>

    <joint name="right_wheel_joint" type="continuous">
        <axis xyz="0.0 0.0 1" />
        <parent link="base_link" />
        <child link="right_wheel" />
        <origin xyz="-0.2825 -0.2 0.01" rpy="-1.5708 0.0 0.0" />

    </joint>
    <link name="left_wheel">
        <visual>
            <geometry>
                <cylinder radius="0.25" length="0.1" />
            </geometry>
            <material name="black">
                <color rgba="0.5 0.1 0.5 1" />
            </material>

        </visual>

    </link>

    <joint name="left_wheel_joint" type="continuous">
        <axis xyz="0.0 0.0 1" />
        <parent link="base_link" />
        <child link="left_wheel" />
        <origin xyz="-0.2825 0.2 0.01" rpy="-1.5708 0.0 0.0" />

    </joint>


    <link name="laser_scanner">
        <visual>
            <geometry>
                <box size="0.1 0.1 0.1" />
            </geometry>
        </visual>
    </link>

    <joint name="laser_scanner_joint" type="fixed">
        <axis xyz="0.0 1 0.0" />
        <parent link="base_link" />
        <child link="laser_scanner" />
        <origin xyz="0.0 0.0 0.15" rpy="0.0 0.0 0.0" />
    </joint>

</robot> 